<sdf version='1.6'>
  <world name='default'>
    <light name='sun' type='directional'>
      <cast_shadows>1</cast_shadows>
      <pose frame=''>0 0 10 0 -0 0</pose>
      <diffuse>0.8 0.8 0.8 1</diffuse>
      <specular>0.2 0.2 0.2 1</specular>
      <attenuation>
        <range>1000</range>
        <constant>0.9</constant>
        <linear>0.01</linear>
        <quadratic>0.001</quadratic>
      </attenuation>
      <direction>-0.5 0.1 -0.9</direction>
    </light>
    <model name='ground_plane'>
      <static>1</static>
      <link name='link'>
        <collision name='collision'>
          <geometry>
            <plane>
              <normal>0 0 1</normal>
              <size>100 100</size>
            </plane>
          </geometry>
          <surface>
            <friction>
              <ode>
                <mu>100</mu>
                <mu2>50</mu2>
              </ode>
              <torsional>
                <ode/>
              </torsional>
            </friction>
            <contact>
              <ode/>
            </contact>
            <bounce/>
          </surface>
          <max_contacts>10</max_contacts>
        </collision>
        <visual name='visual'>
          <cast_shadows>0</cast_shadows>
          <geometry>
            <plane>
              <normal>0 0 1</normal>
              <size>100 100</size>
            </plane>
          </geometry>
          <material>
            <script>
              <uri>file://media/materials/scripts/gazebo.material</uri>
              <name>Gazebo/Grey</name>
            </script>
          </material>
        </visual>
        <self_collide>0</self_collide>
        <enable_wind>0</enable_wind>
        <kinematic>0</kinematic>
      </link>
    </model>
    <gravity>0 0 -9.8</gravity>
    <magnetic_field>6e-06 2.3e-05 -4.2e-05</magnetic_field>
    <atmosphere type='adiabatic'/>
    <physics name='default_physics' default='0' type='ode'>
      <max_step_size>0.001</max_step_size>
      <real_time_factor>1</real_time_factor>
      <real_time_update_rate>1000</real_time_update_rate>
    </physics>
    <scene>
      <ambient>0.4 0.4 0.4 1</ambient>
      <background>0.7 0.7 0.7 1</background>
      <shadows>1</shadows>
    </scene>
    <audio>
      <device>default</device>
    </audio>
    <wind/>
    <spherical_coordinates>
      <surface_model>EARTH_WGS84</surface_model>
      <latitude_deg>0</latitude_deg>
      <longitude_deg>0</longitude_deg>
      <elevation>0</elevation>
      <heading_deg>0</heading_deg>
    </spherical_coordinates>
    <model name='willowgarage'>
      <static>1</static>
      <pose frame=''>-29.7233 -15.665 0 0 -0 0</pose>
      <link name='walls'>
        <collision name='collision'>
          <geometry>
            <mesh>
              <uri>model://willowgarage/meshes/willowgarage_collision.dae</uri>
            </mesh>
          </geometry>
          <max_contacts>10</max_contacts>
          <surface>
            <contact>
              <ode/>
            </contact>
            <bounce/>
            <friction>
              <torsional>
                <ode/>
              </torsional>
              <ode/>
            </friction>
          </surface>
        </collision>
        <visual name='visual'>
          <geometry>
            <mesh>
              <uri>model://willowgarage/meshes/willowgarage_visual.dae</uri>
            </mesh>
          </geometry>
          <cast_shadows>0</cast_shadows>
        </visual>
        <self_collide>0</self_collide>
        <enable_wind>0</enable_wind>
        <kinematic>0</kinematic>
      </link>
    </model>
    <model name='SIM_CER_ROBOT'>
      <link name='mobile_base_body_link'>
        <pose frame=''>0 0 0 0 -0 0</pose>
        <inertial>
          <pose frame=''>0.003532 0 0.062803 0 -0 0</pose>
          <mass>14</mass>
          <inertia>
            <ixx>0.342401</ixx>
            <ixy>0</ixy>
            <ixz>-0.0396992</ixz>
            <iyy>0.362542</iyy>
            <iyz>0</iyz>
            <izz>0.168981</izz>
          </inertia>
        </inertial>
        <collision name='mobile_base_body_link_collision'>
          <pose frame=''>0 0 -0.16 0 -0 0</pose>
          <geometry>
            <mesh>
              <scale>0.001 0.001 0.001</scale>
              <uri>model://cer/meshes/obj/sim_cer_mobilebase_body.obj</uri>
            </mesh>
          </geometry>
          <surface>
            <contact>
              <ode/>
            </contact>
            <friction>
              <ode>
                <mu>0</mu>
                <mu2>0</mu2>
              </ode>
              <torsional>
                <ode/>
              </torsional>
            </friction>
            <bounce/>
          </surface>
          <max_contacts>10</max_contacts>
        </collision>
        <visual name='mobile_base_body_link_visual'>
          <pose frame=''>0 0 -0.16 0 -0 0</pose>
          <geometry>
            <mesh>
              <scale>0.001 0.001 0.001</scale>
              <uri>model://cer/meshes/obj/sim_cer_mobilebase_body.obj</uri>
            </mesh>
          </geometry>
          <material>
            <script>
              <uri>__default__</uri>
              <name>__default__</name>
            </script>
          </material>
        </visual>
        <velocity_decay/>
        <sensor name='base_laser' type='ray'>
          <always_on>1</always_on>
          <update_rate>40</update_rate>
          <pose frame=''>0.07 0 0.031 0 -0 0</pose>
          <visualize>1</visualize>
          <ray>
            <scan>
              <horizontal>
                <samples>360</samples>
                <resolution>2</resolution>
                <min_angle>0</min_angle>
                <max_angle>6.28</max_angle>
              </horizontal>
              <vertical>
                <samples>1</samples>
                <min_angle>0</min_angle>
                <max_angle>0</max_angle>
              </vertical>
            </scan>
            <range>
              <min>0.04</min>
              <max>5</max>
              <resolution>0.01</resolution>
            </range>
            <noise>
              <type>gaussian</type>
              <mean>0</mean>
              <stddev>0.005</stddev>
            </noise>
          </ray>
          <plugin name='laser_sensor' filename='libgazebo_yarp_lasersensor.so'>
            <yarpConfigurationFile>model://cer/conf/gazebo_cer_laser_sensor.ini</yarpConfigurationFile>
          </plugin>
        </sensor>
        <sensor name='base_laser2' type='ray'>
          <always_on>1</always_on>
          <update_rate>40</update_rate>
          <pose frame=''>-0.085 0 0.031 0 -0 3.14159</pose>
          <visualize>1</visualize>
          <ray>
            <scan>
              <horizontal>
                <samples>360</samples>
                <resolution>2</resolution>
                <min_angle>0</min_angle>
                <max_angle>6.28</max_angle>
              </horizontal>
              <vertical>
                <samples>1</samples>
                <min_angle>0</min_angle>
                <max_angle>0</max_angle>
              </vertical>
            </scan>
            <range>
              <min>0.04</min>
              <max>5</max>
              <resolution>0.01</resolution>
            </range>
            <noise>
              <type>gaussian</type>
              <mean>0</mean>
              <stddev>0.005</stddev>
            </noise>
          </ray>
          <plugin name='laser_sensor2' filename='libgazebo_yarp_lasersensor.so'>
            <yarpConfigurationFile>model://cer/conf/gazebo_cer_laser_sensor2.ini</yarpConfigurationFile>
          </plugin>
        </sensor>
        <gravity>1</gravity>
        <velocity_decay/>
        <self_collide>0</self_collide>
        <enable_wind>0</enable_wind>
        <kinematic>0</kinematic>
      </link>
      <link name='mobile_base_l_tyre_link'>
        <pose frame=''>0 0.139 0 0 -0 0</pose>
        <inertial>
          <pose frame=''>0 0.034425 9e-06 0 -0 0</pose>
          <mass>3</mass>
          <inertia>
            <ixx>0.0200196</ixx>
            <ixy>0</ixy>
            <ixz>0</ixz>
            <iyy>0.0376169</iyy>
            <iyz>-8.28446e-07</iyz>
            <izz>0.0200156</izz>
          </inertia>
        </inertial>
        <collision name='mobile_base_l_tyre_link_collision'>
          <pose frame=''>0 0.03 0 1.5708 -0 0</pose>
          <geometry>
            <cylinder>
              <length>0.005</length>
              <radius>0.16</radius>
            </cylinder>
          </geometry>
          <max_contacts>10</max_contacts>
          <surface>
            <contact>
              <ode/>
            </contact>
            <bounce/>
            <friction>
              <torsional>
                <ode/>
              </torsional>
              <ode/>
            </friction>
          </surface>
        </collision>
        <visual name='mobile_base_l_tyre_link_visual'>
          <pose frame=''>0 -0.139 -0.16 0 -0 0</pose>
          <geometry>
            <mesh>
              <scale>0.001 0.001 0.001</scale>
              <uri>model://cer/meshes/dae/sim_cer_mobilebase_l_tyre.dae</uri>
            </mesh>
          </geometry>
        </visual>
        <self_collide>0</self_collide>
        <enable_wind>0</enable_wind>
        <kinematic>0</kinematic>
      </link>
      <joint name='mobile_base_l_wheel_joint' type='revolute'>
        <child>mobile_base_l_tyre_link</child>
        <parent>mobile_base_body_link</parent>
        <axis>
          <xyz>0 1 0</xyz>
          <limit>
            <lower>-1e+16</lower>
            <upper>1e+16</upper>
          </limit>
          <dynamics>
            <damping>0.5</damping>
            <friction>0</friction>
            <spring_reference>0</spring_reference>
            <spring_stiffness>0</spring_stiffness>
          </dynamics>
          <use_parent_model_frame>1</use_parent_model_frame>
        </axis>
        <physics>
          <ode>
            <implicit_spring_damper>1</implicit_spring_damper>
            <cfm_damping>1</cfm_damping>
            <limit>
              <cfm>0</cfm>
              <erp>0.2</erp>
            </limit>
          </ode>
        </physics>
      </joint>
      <link name='mobile_base_r_tyre_link'>
        <pose frame=''>0 -0.139 0 0 -0 0</pose>
        <inertial>
          <pose frame=''>0 -0.034425 9e-06 0 -0 0</pose>
          <mass>3</mass>
          <inertia>
            <ixx>0.0200196</ixx>
            <ixy>0</ixy>
            <ixz>0</ixz>
            <iyy>0.0376169</iyy>
            <iyz>8.28101e-07</iyz>
            <izz>0.0200156</izz>
          </inertia>
        </inertial>
        <collision name='mobile_base_r_tyre_link_collision'>
          <pose frame=''>0 -0.03 0 1.5708 -0 0</pose>
          <geometry>
            <cylinder>
              <length>0.005</length>
              <radius>0.16</radius>
            </cylinder>
          </geometry>
          <max_contacts>10</max_contacts>
          <surface>
            <contact>
              <ode/>
            </contact>
            <bounce/>
            <friction>
              <torsional>
                <ode/>
              </torsional>
              <ode/>
            </friction>
          </surface>
        </collision>
        <visual name='mobile_base_r_tyre_link_visual'>
          <pose frame=''>0 0.139 -0.16 0 -0 0</pose>
          <geometry>
            <mesh>
              <scale>0.001 0.001 0.001</scale>
              <uri>model://cer/meshes/dae/sim_cer_mobilebase_r_tyre.dae</uri>
            </mesh>
          </geometry>
        </visual>
        <self_collide>0</self_collide>
        <enable_wind>0</enable_wind>
        <kinematic>0</kinematic>
      </link>
      <joint name='mobile_base_r_wheel_joint' type='revolute'>
        <child>mobile_base_r_tyre_link</child>
        <parent>mobile_base_body_link</parent>
        <axis>
          <xyz>0 1 0</xyz>
          <limit>
            <lower>-1e+16</lower>
            <upper>1e+16</upper>
          </limit>
          <dynamics>
            <damping>0.5</damping>
            <friction>0</friction>
            <spring_reference>0</spring_reference>
            <spring_stiffness>0</spring_stiffness>
          </dynamics>
          <use_parent_model_frame>1</use_parent_model_frame>
        </axis>
        <physics>
          <ode>
            <implicit_spring_damper>1</implicit_spring_damper>
            <cfm_damping>1</cfm_damping>
            <limit>
              <cfm>0</cfm>
              <erp>0.2</erp>
            </limit>
          </ode>
        </physics>
      </joint>
      <plugin name='controlboard_mobile_base' filename='libgazebo_yarp_controlboard.so'>
        <yarpConfigurationFile>model://cer/conf/gazebo_cer_mobile_base.ini</yarpConfigurationFile>
      </plugin>
      <plugin name='world_interface' filename='libgazebo_yarp_worldinterface.so'>
        <yarpConfigurationFile>model://cer/conf/worldInterface.ini</yarpConfigurationFile>
      </plugin>
      <plugin name='double_laser' filename='libgazebo_yarp_doublelaser.so'>
        <yarpConfigurationFile>model://cer/conf/gazebo_cer_doublelaser.ini</yarpConfigurationFile>
      </plugin>
      <static>0</static>
      <pose frame=''>0.060888 -0.068901 0.16 0 -0 0</pose>
    </model>
    <state world_name='default'>
      <sim_time>97 914000000</sim_time>
      <real_time>98 904237588</real_time>
      <wall_time>1568368961 124428028</wall_time>
      <iterations>97914</iterations>
      <model name='SIM_CER_ROBOT'>
        <pose frame=''>0.071132 -0.06694 0.159998 -9e-06 0.00842 -0.001016</pose>
        <scale>1 1 1</scale>
        <link name='mobile_base_body_link'>
          <pose frame=''>0.071132 -0.06694 0.159998 -9e-06 0.00842 -0.001016</pose>
          <velocity>0.000397 0.000809 0.00012 -0.017549 -0.000812 -0.002271</velocity>
          <acceleration>-0.062928 3.66193 0.190438 -0.99787 -1.30144 -1.67837</acceleration>
          <wrench>-0.880991 51.267 2.66614 0 -0 0</wrench>
        </link>
        <link name='mobile_base_l_tyre_link'>
          <pose frame=''>0.071273 0.072058 0.159999 -5.1e-05 0.008421 -0.001017</pose>
          <velocity>0.000719 0.001252 -0.002676 -0.006904 0.001315 -0.002268</velocity>
          <acceleration>0.84646 2.34478 -5.94137 1.62918 1.53874 -1.35698</acceleration>
          <wrench>2.53938 7.03435 -17.8241 0 -0 0</wrench>
        </link>
        <link name='mobile_base_r_tyre_link'>
          <pose frame=''>0.070991 -0.205938 0.160001 4.2e-05 0.008421 -0.001016</pose>
          <velocity>8.4e-05 0.001191 0.002976 -0.007723 0.000105 -0.002269</velocity>
          <acceleration>-0.72304 2.22969 6.48319 -2.97344 1.21134 1.78379</acceleration>
          <wrench>-2.16912 6.68907 19.4496 0 -0 0</wrench>
        </link>
      </model>
      <model name='ground_plane'>
        <pose frame=''>0 0 0 0 -0 0</pose>
        <scale>1 1 1</scale>
        <link name='link'>
          <pose frame=''>0 0 0 0 -0 0</pose>
          <velocity>0 0 0 0 -0 0</velocity>
          <acceleration>0 0 0 0 -0 0</acceleration>
          <wrench>0 0 0 0 -0 0</wrench>
        </link>
      </model>
      <model name='willowgarage'>
        <pose frame=''>-27.5567 -12.3051 0 0 -0 0</pose>
        <scale>1 1 1</scale>
        <link name='walls'>
          <pose frame=''>-27.5567 -12.3051 0 0 -0 0</pose>
          <velocity>0 0 0 0 -0 0</velocity>
          <acceleration>0 0 0 0 -0 0</acceleration>
          <wrench>0 0 0 0 -0 0</wrench>
        </link>
      </model>
      <light name='sun'>
        <pose frame=''>0 0 10 0 -0 0</pose>
      </light>
    </state>
    <gui fullscreen='0'>
      <camera name='user_camera'>
        <pose frame=''>8.91783 -18.4805 53.6906 0 1.29164 1.5282</pose>
        <view_controller>orbit</view_controller>
        <projection_type>perspective</projection_type>
      </camera>
    </gui>
  </world>
</sdf>
